2022-01-12 11:28:14,669	INFO agent.py:90 -- Parent pid is 159752
2022-01-12 11:28:14,670	INFO agent.py:95 -- Dashboard agent grpc address: 0.0.0.0:43657
2022-01-12 11:28:14,675	INFO utils.py:200 -- Get all modules by type: DashboardAgentModule
2022-01-12 11:28:15,179	WARNING tune_head.py:22 -- tune module is not available: cannot import name 'Analysis' from 'ray.tune' (/home/reza/anaconda3/lib/python3.8/site-packages/ray/tune/__init__.py)
2022-01-12 11:28:15,179	INFO agent.py:109 -- Loading DashboardAgentModule: <class 'ray.dashboard.modules.event.event_agent.EventAgent'>
2022-01-12 11:28:15,179	INFO event_agent.py:30 -- Event agent cache buffer size: 10240
2022-01-12 11:28:15,179	INFO agent.py:109 -- Loading DashboardAgentModule: <class 'ray.dashboard.modules.log.log_agent.LogAgent'>
2022-01-12 11:28:15,179	INFO agent.py:109 -- Loading DashboardAgentModule: <class 'ray.dashboard.modules.reporter.reporter_agent.ReporterAgent'>
2022-01-12 11:28:15,181	INFO agent.py:109 -- Loading DashboardAgentModule: <class 'ray.dashboard.modules.runtime_env.runtime_env_agent.RuntimeEnvAgent'>
2022-01-12 11:28:15,181	INFO agent.py:114 -- Loaded 4 modules.
2022-01-12 11:28:15,182	INFO agent.py:191 -- Dashboard agent http address: 0.0.0.0:44011
2022-01-12 11:28:15,182	INFO agent.py:199 -- <ResourceRoute [GET] <StaticResource  /logs -> PosixPath('/home/reza/Dropbox/Prog/MERA/temp/session_2022-01-12_11-28-11_918402_159639/logs')> -> <bound method StaticResource._handle of <StaticResource  /logs -> PosixPath('/home/reza/Dropbox/Prog/MERA/temp/session_2022-01-12_11-28-11_918402_159639/logs')>>
2022-01-12 11:28:15,182	INFO agent.py:199 -- <ResourceRoute [OPTIONS] <StaticResource  /logs -> PosixPath('/home/reza/Dropbox/Prog/MERA/temp/session_2022-01-12_11-28-11_918402_159639/logs')> -> <bound method _PreflightHandler._preflight_handler of <aiohttp_cors.cors_config._CorsConfigImpl object at 0x7f988f871700>>
2022-01-12 11:28:15,182	INFO agent.py:200 -- Registered 2 routes.
2022-01-12 11:28:15,184	INFO event_agent.py:47 -- Report events to b'131.215.21.210:45791'
2022-01-12 11:28:15,185	INFO event_utils.py:123 -- Monitor events logs modified after 1642013894.6847243 on /home/reza/Dropbox/Prog/MERA/temp/session_2022-01-12_11-28-11_918402_159639/logs/events, the source types are ['COMMON', 'RAYLET', 'CORE_WORKER'].
2022-01-12 11:29:18,460	ERROR gcs_utils.py:136 -- Failed to send request to gcs, reconnecting. Error <_InactiveRpcError of RPC that terminated with:
	status = StatusCode.UNAVAILABLE
	details = "Socket closed"
	debug_error_string = "{"created":"@1642015758.459973568","description":"Error received from peer ipv4:131.215.21.210:37957","file":"src/core/lib/surface/call.cc","file_line":1061,"grpc_message":"Socket closed","grpc_status":14}"
>
2022-01-12 11:29:19,461	ERROR gcs_utils.py:136 -- Failed to send request to gcs, reconnecting. Error <_InactiveRpcError of RPC that terminated with:
	status = StatusCode.UNAVAILABLE
	details = "failed to connect to all addresses"
	debug_error_string = "{"created":"@1642015759.461741852","description":"Failed to pick subchannel","file":"src/core/ext/filters/client_channel/client_channel.cc","file_line":4133,"referenced_errors":[{"created":"@1642015759.461740026","description":"failed to connect to all addresses","file":"src/core/ext/filters/client_channel/lb_policy/pick_first/pick_first.cc","file_line":397,"grpc_status":14}]}"
>
2022-01-12 11:29:20,463	ERROR gcs_utils.py:136 -- Failed to send request to gcs, reconnecting. Error <_InactiveRpcError of RPC that terminated with:
	status = StatusCode.UNAVAILABLE
	details = "failed to connect to all addresses"
	debug_error_string = "{"created":"@1642015760.463379203","description":"Failed to pick subchannel","file":"src/core/ext/filters/client_channel/client_channel.cc","file_line":4133,"referenced_errors":[{"created":"@1642015760.463377316","description":"failed to connect to all addresses","file":"src/core/ext/filters/client_channel/lb_policy/pick_first/pick_first.cc","file_line":397,"grpc_status":14}]}"
>
2022-01-12 11:29:21,465	ERROR gcs_utils.py:136 -- Failed to send request to gcs, reconnecting. Error <_InactiveRpcError of RPC that terminated with:
	status = StatusCode.UNAVAILABLE
	details = "failed to connect to all addresses"
	debug_error_string = "{"created":"@1642015761.464989433","description":"Failed to pick subchannel","file":"src/core/ext/filters/client_channel/client_channel.cc","file_line":4133,"referenced_errors":[{"created":"@1642015761.464978650","description":"failed to connect to all addresses","file":"src/core/ext/filters/client_channel/lb_policy/pick_first/pick_first.cc","file_line":397,"grpc_status":14}]}"
>
2022-01-12 11:29:22,468	ERROR gcs_utils.py:136 -- Failed to send request to gcs, reconnecting. Error <_InactiveRpcError of RPC that terminated with:
	status = StatusCode.UNAVAILABLE
	details = "failed to connect to all addresses"
	debug_error_string = "{"created":"@1642015762.467967156","description":"Failed to pick subchannel","file":"src/core/ext/filters/client_channel/client_channel.cc","file_line":4133,"referenced_errors":[{"created":"@1642015762.467964138","description":"failed to connect to all addresses","file":"src/core/ext/filters/client_channel/lb_policy/pick_first/pick_first.cc","file_line":397,"grpc_status":14}]}"
>
2022-01-12 11:29:23,469	ERROR reporter_agent.py:545 -- Error publishing node physical stats.
Traceback (most recent call last):
  File "/home/reza/anaconda3/lib/python3.8/site-packages/ray/dashboard/modules/reporter/reporter_agent.py", line 534, in _perform_iteration
    formatted_status_string = internal_kv._internal_kv_get(
  File "/home/reza/anaconda3/lib/python3.8/site-packages/ray/_private/client_mode_hook.py", line 105, in wrapper
    return func(*args, **kwargs)
  File "/home/reza/anaconda3/lib/python3.8/site-packages/ray/experimental/internal_kv.py", line 43, in _internal_kv_get
    return global_gcs_client.internal_kv_get(key, namespace)
  File "/home/reza/anaconda3/lib/python3.8/site-packages/ray/_private/gcs_utils.py", line 130, in wrapper
    return f(self, *args, **kwargs)
  File "/home/reza/anaconda3/lib/python3.8/site-packages/ray/_private/gcs_utils.py", line 233, in internal_kv_get
    reply = self._kv_stub.InternalKVGet(req)
  File "/home/reza/.local/lib/python3.8/site-packages/grpc/_channel.py", line 826, in __call__
    return _end_unary_response_blocking(state, call, False, None)
  File "/home/reza/.local/lib/python3.8/site-packages/grpc/_channel.py", line 729, in _end_unary_response_blocking
    raise _InactiveRpcError(state)
grpc._channel._InactiveRpcError: <_InactiveRpcError of RPC that terminated with:
	status = StatusCode.UNAVAILABLE
	details = "failed to connect to all addresses"
	debug_error_string = "{"created":"@1642015763.469816851","description":"Failed to pick subchannel","file":"src/core/ext/filters/client_channel/client_channel.cc","file_line":4133,"referenced_errors":[{"created":"@1642015763.469815021","description":"failed to connect to all addresses","file":"src/core/ext/filters/client_channel/lb_policy/pick_first/pick_first.cc","file_line":397,"grpc_status":14}]}"
>
2022-01-12 11:29:23,470	ERROR agent.py:126 -- Raylet is dead, exiting.
